Workbook
Name Slicer_Diabetes_status: #N/A
Name Slicer_Diabetes_status1: #N/A
Name Slicer_Heart_Issues: #N/A
Name Slicer_Hospital_tier: #N/A
Name Slicer_Smoker: #N/A
Name Slicer_State_ID: #N/A
Name Slicer_Weight_Status: #N/A
Name Slicer_Weight_Status1: #N/A

Sheet Customer Names
A1: Customer ID | B1: Last Name | C1: Title | D1: First Name
A2: Id1 | B2: Hawks | C2: Ms. | D2: Kelly
A3: Id2 | B3: Lehner | C3: Mr. | D3: Matthew D
A4: Id3 | B4: Lu | C4: Mr. | D4: Phil
A5: Id4 | B5: Osborne | C5: Ms. | D5: Kelsey
A6: Id5 | B6: Kadala | C6: Ms. | D6: Kristyn
A7: Id6 | B7: Baker | C7: Mr. | D7: Russell B.
A8: Id7 | B8: Macpherson | C8: Mr. | D8: Scott
A9: Id8 | B9: Hallman | C9: Mr. | D9: Stephen
A10: Id9 | B10: Moran | C10: Mr. | D10: Patrick R.
A11: Id10 | B11: Benner | C11: Ms. | D11: Brooke N.
A12: Id11 | B12: Fierro Vargas | C12: Ms. | D12: Paola Andrea
... A2336: Id2335 | B2336: German | C2336: Mr. | D2336: Aaron K

Sheet Hospitalisation Details
A1: Customer ID | B1: Date of Birth | C1: children | D1: charges | E1: Hospital tier | F1: City tier | G1: State ID | H1: Age
A2: Id2335 | B2: 33794 | C2: 0 | D2: 563.84 | E2: tier - 2 | F2: tier - 3 | G2: R1013 | H2: =DATEDIF(B2,DATE(2023,6,8),"y") -> 30
A3: Id2334 | B3: 33938 | C3: 0 | D3: 570.62 | E3: tier - 2 | F3: tier - 1 | G3: R1013 | H3: =DATEDIF(B3,DATE(2023,6,8),"y") -> 30
A4: Id2333 | B4: 34150 | C4: 0 | D4: 600 | E4: tier - 2 | F4: tier - 1 | G4: R1013 | H4: =DATEDIF(B4,DATE(2023,6,8),"y") -> 29 | I4: NUMBER OF MISSING VALUES FOR CUSTOMER ID | L4: =COUNTIF(A:A,"?") -> 6
A5: Id2332 | B5: 33860 | C5: 0 | D5: 604.54 | E5: tier - 3 | F5: tier - 3 | G5: R1013 | H5: =DATEDIF(B5,DATE(2023,6,8),"y") -> 30 | I5: NUMBER OF MISSING VALUES FOR MONTH | L5: =COUNTIF(B:B,"Jan") -> 0
A6: Id2331 | B6: 36003 | C6: 0 | D6: 637.26 | E6: tier - 3 | F6: tier - 3 | G6: R1013 | H6: =DATEDIF(B6,DATE(2023,6,8),"y") -> 24 | I6: NUMBER OF MISSING VALUES FOR HOSPITAL TIER | L6: =COUNTIF(E:E,"?") -> 0
A7: Id2330 | B7: 37215 | C7: 0 | D7: 646.14 | E7: tier - 3 | F7: tier - 3 | G7: R1012 | H7: =DATEDIF(B7,DATE(2023,6,8),"y") -> 21 | I7: NUMBER OF MISSING VALUES FOR CITY TIER | L7: =COUNTIF(F:F,"?") -> 0
A8: Id2329 | B8: 34121 | C8: 0 | D8: 650 | E8: tier - 3 | F8: tier - 3 | G8: R1013 | H8: =DATEDIF(B8,DATE(2023,6,8),"y") -> 30 | I8: NUMBER OF MISSING VALUES FOR STATE ID | L8: =COUNTIF(G:G,"?") -> 0
A9: Id2328 | B9: 34884 | C9: 0 | D9: 650 | E9: tier - 3 | F9: tier - 3 | G9: R1013 | H9: =DATEDIF(B9,DATE(2023,6,8),"y") -> 27
A10: Id2327 | B10: 37589 | C10: 0 | D10: 668 | E10: tier - 3 | F10: tier - 2 | G10: R1012 | H10: =DATEDIF(B10,DATE(2023,6,8),"y") -> 20
A11: Id2326 | B11: 35743 | C11: 0 | D11: 670 | E11: tier - 3 | F11: tier - 3 | G11: R1013 | H11: =DATEDIF(B11,DATE(2023,6,8),"y") -> 25
A12: Id2325 | B12: 37146 | C12: 0 | D12: 687.54 | E12: tier - 3 | F12: tier - 2 | G12: R1013 | H12: =DATEDIF(B12,DATE(2023,6,8),"y") -> 21 | J12: Month | K12: Number
A13: Id2324 | B13: 36520 | C13: 0 | D13: 700 | E13: tier - 3 | F13: tier - 3 | G13: R1013 | H13: =DATEDIF(B13,DATE(2023,6,8),"y") -> 23 | J13: Jan | K13: 1
A14: Id2323 | B14: 36508 | C14: 0 | D14: 722.99 | E14: tier - 3 | F14: tier - 1 | G14: R1013 | H14: =DATEDIF(B14,DATE(2023,6,8),"y") -> 23 | J14: Feb | K14: 2
A15: Id2322 | B15: 37518 | C15: 0 | D15: 750 | E15: tier - 3 | F15: tier - 1 | G15: R1012 | H15: =DATEDIF(B15,DATE(2023,6,8),"y") -> 20 | J15: Mar | K15: 3
A16: Id2321 | B16: 34190 | C16: 0 | D16: 760 | E16: tier - 3 | F16: tier - 1 | G16: R1013 | H16: =DATEDIF(B16,DATE(2023,6,8),"y") -> 29 | J16: Apr | K16: 4
A17: Id2320 | B17: 35360 | C17: 0 | D17: 760 | E17: tier - 3 | F17: tier - 3 | G17: R1013 | H17: =DATEDIF(B17,DATE(2023,6,8),"y") -> 26 | J17: May | K17: 5
A18: Id2319 | B18: 34148 | C18: 0 | D18: 770 | E18: tier - 3 | F18: tier - 3 | G18: R1013 | H18: =DATEDIF(B18,DATE(2023,6,8),"y") -> 29 | J18: Jun | K18: 6
A19: Id2318 | B19: 35326 | C19: 0 | D19: 770.38 | E19: tier - 3 | F19: tier - 3 | G19: R1012 | H19: =DATEDIF(B19,DATE(2023,6,8),"y") -> 26 | J19: Jul | K19: 7
A20: Id2317 | B20: 35040 | C20: 0 | D20: 773.54 | E20: tier - 3 | F20: tier - 2 | G20: R1013 | H20: =DATEDIF(B20,DATE(2023,6,8),"y") -> 27 | J20: Aug | K20: 8
A21: Id2316 | B21: 38267 | C21: 0 | D21: 830.52 | E21: tier - 3 | F21: tier - 2 | G21: R1011 | H21: =DATEDIF(B21,DATE(2023,6,8),"y") -> 18 | J21: Sep | K21: 9
A22: Id2315 | B22: 36848 | C22: 0 | D22: 865.41 | E22: tier - 3 | F22: tier - 1 | G22: R1013 | H22: =DATEDIF(B22,DATE(2023,6,8),"y") -> 22 | J22: Oct | K22: 10
A23: Id2314 | B23: 34300 | C23: 0 | D23: 896.21 | E23: tier - 3 | F23: tier - 1 | G23: R1013 | H23: =DATEDIF(B23,DATE(2023,6,8),"y") -> 29 | J23: Nov | K23: 11
A24: Id2313 | B24: 34637 | C24: 0 | D24: 915.07 | E24: tier - 3 | F24: tier - 1 | G24: R1013 | H24: =DATEDIF(B24,DATE(2023,6,8),"y") -> 28 | J24: Dec | K24: 12
A25: Id2312 | B25: 35000 | C25: 0 | D25: 928.59 | E25: tier - 3 | F25: tier - 1 | G25: R1013 | H25: =DATEDIF(B25,DATE(2023,6,8),"y") -> 27
A26: Id2311 | B26: 37122 | C26: 0 | D26: 964.71 | E26: tier - 3 | F26: tier - 2 | G26: R1013 | H26: =DATEDIF(B26,DATE(2023,6,8),"y") -> 21
A27: Id2310 | B27: 34660 | C27: 0 | D27: 1006.65 | E27: tier - 3 | F27: tier - 2 | G27: R1013 | H27: =DATEDIF(B27,DATE(2023,6,8),"y") -> 28
A28: Id2309 | B28: 36808 | C28: 0 | D28: 1012 | E28: tier - 3 | F28: tier - 2 | G28: R1013 | H28: =DATEDIF(B28,DATE(2023,6,8),"y") -> 22
A29: Id2308 | B29: 36377 | C29: 0 | D29: 1019 | E29: tier - 3 | F29: tier - 2 | G29: R1013 | H29: =DATEDIF(B29,DATE(2023,6,8),"y") -> 23
A30: Id2307 | B30: 34977 | C30: 0 | D30: 1033.74 | E30: tier - 3 | F30: tier - 1 | G30: R1013 | H30: =DATEDIF(B30,DATE(2023,6,8),"y") -> 27
A31: Id2306 | B31: 34655 | C31: 0 | D31: 1044 | E31: tier - 3 | F31: tier - 2 | G31: R1013 | H31: =DATEDIF(B31,DATE(2023,6,8),"y") -> 28
A32: Id2305 | B32: 37457 | C32: 0 | D32: 1047 | E32: tier - 3 | F32: tier - 1 | G32: R1013 | H32: =DATEDIF(B32,DATE(2023,6,8),"y") -> 20
A33: Id2304 | B33: 37438 | C33: 0 | D33: 1049 | E33: tier - 3 | F33: tier - 2 | G33: R1012 | H33: =DATEDIF(B33,DATE(2023,6,8),"y") -> 20
A34: Id2303 | B34: 34851 | C34: 0 | D34: 1056 | E34: tier - 3 | F34: tier - 2 | G34: R1013 | H34: =DATEDIF(B34,DATE(2023,6,8),"y") -> 28
A35: Id2302 | B35: 34240 | C35: 0 | D35: 1068 | E35: tier - 3 | F35: tier - 1 | G35: R1013 | H35: =DATEDIF(B35,DATE(2023,6,8),"y") -> 29
A36: Id2301 | B36: 38223 | C36: 0 | D36: 1070 | E36: tier - 3 | F36: tier - 3 | G36: R1013 | H36: =DATEDIF(B36,DATE(2023,6,8),"y") -> 18
... A1050: Id1290 | B1050: 28332 | C1050: 2 | D1050: 8527.53 | E1050: tier - 2 | F1050: tier - 2 | G1050: R1013 | H1050: =DATEDIF(B1050,DATE(2023,6,8),"y") -> 45
A1051: Id1289 | B1051: 24-7-1982.84152071764 | C1051: 0 | D1051: 8534.67 | E1051: tier - 2 | F1051: tier - 3 | G1051: R1024 | H1051: =DATEDIF(B1051,DATE(2023,6,8),"y") -> #VALUE!
A1052: Id1288 | B1052: 29947 | C1052: 3 | D1052: 8538.29 | E1052: tier - 2 | F1052: tier - 3 | G1052: R1024 | H1052: =DATEDIF(B1052,DATE(2023,6,8),"y") -> 41
A1053: Id1287 | B1053: 27704 | C1053: 1 | D1053: 8539.67 | E1053: tier - 2 | F1053: tier - 3 | G1053: R1011 | H1053: =DATEDIF(B1053,DATE(2023,6,8),"y") -> 47
...

Sheet Medical Examinations
A1: Customer ID | B1: BMI | C1: HBA1C | D1: Heart Issues | E1: Any Transplants | F1: Cancer history | G1: Number of Major Surgeries | H1: Smoker | I1: Weight Status | J1: Diabetes status
A2: Id2335 | B2: 47.41 | C2: 7.47 | D2: No | E2: No | F2: No | G2: 0 | H2: yes | I2: =IF(B2<18.5,"Under Weight",IF(B2<=24.9,"Normal Weight",IF(B2<=29.9,"Over Weight","Obesity"))) -> Obesity | J2: =IF(C2<5.7,"Normal",IF(C2<=6.4,"Prediabetes","Diabetes")) -> Diabetes
A3: Id2334 | B3: 30.36 | C3: 5.77 | D3: No | E3: No | F3: No | G3: 0 | H3: yes | I3: =IF(B3<18.5,"Under Weight",IF(B3<=24.9,"Normal Weight",IF(B3<=29.9,"Over Weight","Obesity"))) -> Obesity | J3: =IF(C3<5.7,"Normal",IF(C3<=6.4,"Prediabetes","Diabetes")) -> Prediabetes
A4: Id2333 | B4: 34.485 | C4: 11.87 | D4: Yes | E4: No | F4: No | G4: 2 | H4: yes | I4: =IF(B4<18.5,"Under Weight",IF(B4<=24.9,"Normal Weight",IF(B4<=29.9,"Over Weight","Obesity"))) -> Obesity | J4: =IF(C4<5.7,"Normal",IF(C4<=6.4,"Prediabetes","Diabetes")) -> Diabetes
A5: Id2332 | B5: 38.095 | C5: 6.05 | D5: No | E5: No | F5: No | G5: 0 | H5: yes | I5: =IF(B5<18.5,"Under Weight",IF(B5<=24.9,"Normal Weight",IF(B5<=29.9,"Over Weight","Obesity"))) -> Obesity | J5: =IF(C5<5.7,"Normal",IF(C5<=6.4,"Prediabetes","Diabetes")) -> Prediabetes | K5: Data Cleaning:
A6: Id2331 | B6: 35.53 | C6: 5.45 | D6: No | E6: No | F6: No | G6: 0 | H6: yes | I6: =IF(B6<18.5,"Under Weight",IF(B6<=24.9,"Normal Weight",IF(B6<=29.9,"Over Weight","Obesity"))) -> Obesity | J6: =IF(C6<5.7,"Normal",IF(C6<=6.4,"Prediabetes","Diabetes")) -> Normal | K6: 1) Check for the number of missing values marked with '?' in each column of the "Medical
A7: Id2330 | B7: 32.8 | C7: 6.59 | D7: No | E7: No | F7: No | G7: 0 | H7: yes | I7: =IF(B7<18.5,"Under Weight",IF(B7<=24.9,"Normal Weight",IF(B7<=29.9,"Over Weight","Obesity"))) -> Obesity | J7: =IF(C7<5.7,"Normal",IF(C7<=6.4,"Prediabetes","Diabetes")) -> Diabetes | K7: Examinations" table and "Hospitalization Details" table.
A8: Id2329 | B8: 36.4 | C8: 6.07 | D8: No | E8: No | F8: No | G8: 0 | H8: yes | I8: =IF(B8<18.5,"Under Weight",IF(B8<=24.9,"Normal Weight",IF(B8<=29.9,"Over Weight","Obesity"))) -> Obesity | J8: =IF(C8<5.7,"Normal",IF(C8<=6.4,"Prediabetes","Diabetes")) -> Prediabetes
A9: Id2328 | B9: 36.96 | C9: 7.93 | D9: No | E9: No | F9: No | G9: 3 | H9: yes | I9: =IF(B9<18.5,"Under Weight",IF(B9<=24.9,"Normal Weight",IF(B9<=29.9,"Over Weight","Obesity"))) -> Obesity | J9: =IF(C9<5.7,"Normal",IF(C9<=6.4,"Prediabetes","Diabetes")) -> Diabetes | K9: NUMBER OF MISSING VALUES IN SMOKER
A10: Id2327 | B10: 41.14 | C10: 9.58 | D10: Yes | E10: No | F10: Yes | G10: 1 | H10: yes | I10: =IF(B10<18.5,"Under Weight",IF(B10<=24.9,"Normal Weight",IF(B10<=29.9,"Over Weight","Obesity"))) -> Obesity | J10: =IF(C10<5.7,"Normal",IF(C10<=6.4,"Prediabetes","Diabetes")) -> Diabetes
A11: Id2326 | B11: 38.06 | C11: 10.79 | D11: No | E11: No | F11: No | G11: 0 | H11: yes | I11: =IF(B11<18.5,"Under Weight",IF(B11<=24.9,"Normal Weight",IF(B11<=29.9,"Over Weight","Obesity"))) -> Obesity | J11: =IF(C11<5.7,"Normal",IF(C11<=6.4,"Prediabetes","Diabetes")) -> Diabetes
A12: Id2325 | B12: 37.7 | C12: 5.96 | D12: Yes | E12: No | F12: No | G12: 2 | H12: yes | I12: =IF(B12<18.5,"Under Weight",IF(B12<=24.9,"Normal Weight",IF(B12<=29.9,"Over Weight","Obesity"))) -> Obesity | J12: =IF(C12<5.7,"Normal",IF(C12<=6.4,"Prediabetes","Diabetes")) -> Prediabetes
A13: Id2324 | B13: 42.13 | C13: 11.9 | D13: No | E13: No | F13: No | G13: 0 | H13: yes | I13: =IF(B13<18.5,"Under Weight",IF(B13<=24.9,"Normal Weight",IF(B13<=29.9,"Over Weight","Obesity"))) -> Obesity | J13: =IF(C13<5.7,"Normal",IF(C13<=6.4,"Prediabetes","Diabetes")) -> Diabetes
A14: Id2323 | B14: 40.92 | C14: 8.41 | D14: No | E14: No | F14: No | G14: 0 | H14: yes | I14: =IF(B14<18.5,"Under Weight",IF(B14<=24.9,"Normal Weight",IF(B14<=29.9,"Over Weight","Obesity"))) -> Obesity | J14: =IF(C14<5.7,"Normal",IF(C14<=6.4,"Prediabetes","Diabetes")) -> Diabetes
A15: Id2322 | B15: 40.565 | C15: 7.02 | D15: No | E15: No | F15: No | G15: 0 | H15: yes | I15: =IF(B15<18.5,"Under Weight",IF(B15<=24.9,"Normal Weight",IF(B15<=29.9,"Over Weight","Obesity"))) -> Obesity | J15: =IF(C15<5.7,"Normal",IF(C15<=6.4,"Prediabetes","Diabetes")) -> Diabetes
A16: Id2321 | B16: 36.385 | C16: 7.59 | D16: Yes | E16: No | F16: No | G16: 2 | H16: yes | I16: =IF(B16<18.5,"Under Weight",IF(B16<=24.9,"Normal Weight",IF(B16<=29.9,"Over Weight","Obesity"))) -> Obesity | J16: =IF(C16<5.7,"Normal",IF(C16<=6.4,"Prediabetes","Diabetes")) -> Diabetes
A17: Id2320 | B17: 39.9 | C17: 11.32 | D17: No | E17: No | F17: No | G17: 0 | H17: yes | I17: =IF(B17<18.5,"Under Weight",IF(B17<=24.9,"Normal Weight",IF(B17<=29.9,"Over Weight","Obesity"))) -> Obesity | J17: =IF(C17<5.7,"Normal",IF(C17<=6.4,"Prediabetes","Diabetes")) -> Diabetes
A18: Id2319 | B18: 33.8 | C18: 7.67 | D18: No | E18: No | F18: No | G18: 3 | H18: yes | I18: =IF(B18<18.5,"Under Weight",IF(B18<=24.9,"Normal Weight",IF(B18<=29.9,"Over Weight","Obesity"))) -> Obesity | J18: =IF(C18<5.7,"Normal",IF(C18<=6.4,"Prediabetes","Diabetes")) -> Diabetes
A19: Id2318 | B19: 36.765 | C19: 7.29 | D19: Yes | E19: No | F19: Yes | G19: 1 | H19: yes | I19: =IF(B19<18.5,"Under Weight",IF(B19<=24.9,"Normal Weight",IF(B19<=29.9,"Over Weight","Obesity"))) -> Obesity | J19: =IF(C19<5.7,"Normal",IF(C19<=6.4,"Prediabetes","Diabetes")) -> Diabetes
A20: Id2317 | B20: 36.955 | C20: 4.72 | D20: Yes | E20: No | F20: No | G20: 1 | H20: yes | I20: =IF(B20<18.5,"Under Weight",IF(B20<=24.9,"Normal Weight",IF(B20<=29.9,"Over Weight","Obesity"))) -> Obesity | J20: =IF(C20<5.7,"Normal",IF(C20<=6.4,"Prediabetes","Diabetes")) -> Normal
A21: Id2316 | B21: 42.9 | C21: 11.41 | D21: No | E21: No | F21: No | G21: 0 | H21: yes | I21: =IF(B21<18.5,"Under Weight",IF(B21<=24.9,"Normal Weight",IF(B21<=29.9,"Over Weight","Obesity"))) -> Obesity | J21: =IF(C21<5.7,"Normal",IF(C21<=6.4,"Prediabetes","Diabetes")) -> Diabetes
... A2336: Id9 | B2336: 17.58 | C2336: 4.51 | D2336: No | E2336: No | F2336: No | G2336: 1 | H2336: No | I2336: =IF(B2336<18.5,"Under Weight",IF(B2336<=24.9,"Normal Weight",IF(B2336<=29.9,"Over Weight","Obesity"))) -> Under Weight | J2336: =IF(C2336<5.7,"Normal",IF(C2336<=6.4,"Prediabetes","Diabetes")) -> Normal
A2337: Id8 | D2337: Check | G2337: 0.67623126 | H2337: No | I2337: =IF(B2337<18.5,"Under Weight",IF(B2337<=24.9,"Normal Weight",IF(B2337<=29.9,"Over Weight","Obesity"))) -> Under Weight | J2337: =IF(C2337<5.7,"Normal",IF(C2337<=6.4,"Prediabetes","Diabetes")) -> Normal
A2338: Id7 | D2338: Check | G2338: 0.67623126 | H2338: No | I2338: =IF(B2338<18.5,"Under Weight",IF(B2338<=24.9,"Normal Weight",IF(B2338<=29.9,"Over Weight","Obesity"))) -> Under Weight | J2338: =IF(C2338<5.7,"Normal",IF(C2338<=6.4,"Prediabetes","Diabetes")) -> Normal
A2339: Id6 | D2339: Check | G2339: 0.67623126 | H2339: No | I2339: =IF(B2339<18.5,"Under Weight",IF(B2339<=24.9,"Normal Weight",IF(B2339<=29.9,"Over Weight","Obesity"))) -> Under Weight | J2339: =IF(C2339<5.7,"Normal",IF(C2339<=6.4,"Prediabetes","Diabetes")) -> Normal
A2340: Id5 | D2340: Check | G2340: 0.67623126 | H2340: No | I2340: =IF(B2340<18.5,"Under Weight",IF(B2340<=24.9,"Normal Weight",IF(B2340<=29.9,"Over Weight","Obesity"))) -> Under Weight | J2340: =IF(C2340<5.7,"Normal",IF(C2340<=6.4,"Prediabetes","Diabetes")) -> Normal
A2341: Id4 | D2341: Check | G2341: 0.67623126 | H2341: No | I2341: =IF(B2341<18.5,"Under Weight",IF(B2341<=24.9,"Normal Weight",IF(B2341<=29.9,"Over Weight","Obesity"))) -> Under Weight | J2341: =IF(C2341<5.7,"Normal",IF(C2341<=6.4,"Prediabetes","Diabetes")) -> Normal
A2342: Id3 | D2342: Check | G2342: 0.67623126 | H2342: No | I2342: =IF(B2342<18.5,"Under Weight",IF(B2342<=24.9,"Normal Weight",IF(B2342<=29.9,"Over Weight","Obesity"))) -> Under Weight | J2342: =IF(C2342<5.7,"Normal",IF(C2342<=6.4,"Prediabetes","Diabetes")) -> Normal
A2343: Id2 | D2343: Check | G2343: 0.67623126 | H2343: No | I2343: =IF(B2343<18.5,"Under Weight",IF(B2343<=24.9,"Normal Weight",IF(B2343<=29.9,"Over Weight","Obesity"))) -> Under Weight | J2343: =IF(C2343<5.7,"Normal",IF(C2343<=6.4,"Prediabetes","Diabetes")) -> Normal
A2344: Id1 | D2344: Check | G2344: 0.67623126 | H2344: No | I2344: =IF(B2344<18.5,"Under Weight",IF(B2344<=24.9,"Normal Weight",IF(B2344<=29.9,"Over Weight","Obesity"))) -> Under Weight | J2344: =IF(C2344<5.7,"Normal",IF(C2344<=6.4,"Prediabetes","Diabetes")) -> Normal

Sheet Cancer history vs smokers
A3: Smoker | B3: Cancer history | C3: Count of Customer ID | D3: Insights/Observation
A4: No | B4: No | C4: 1540 | D4: Most customers are non- smokers and also no cancer history
B5: Yes | C5: 307 | D5: This indicates if some are non-smokers but they have cancer
B6: (blank) | C6: 8 | D6: some customers are smokers but they didn't have cancer
A7: Grand Total | C7: 1855 | D7: minimum number of customers who are smokers they also have cancer history

Sheet Charges by Weight status
A3: Weight Status | B3: Average of charges | C3: Count of Customer ID | D3: Insights/Observation
A4: Normal Weight | B4: 17346.316 | C4: 431 | D4: Moderate charges
A5: Obesity | B5: 10474.625 | C5: 1229 | D5: Lowest average charges,But highest number of customers
A6: Over Weight | B6: 13633.365 | C6: 492 | D6: Mid level charges
A7: Under Weight | B7: 24782.334 | C7: 183 | D7: highest average charges
A8: Grand Total | B8: 13529.918 | C8: 2335

Sheet Diabetes status vs Total custom
A3: Row Labels | B3: Count of Customer ID
A4: Diabetes | B4: 794
A5: Grand Total | B5: 794

Sheet total HBA1C vs city tier
A3: Sum of HBA1C | B3: Diabetes status
A4: City tier | B4: Diabetes | C4: Normal | D4: Prediabetes
A5: tier - 1 | B5: 2292.68 | C5: 1605.44 | D5: 915.25
A6: tier - 2 | B6: 2501.89 | C6: 1811.33 | D6: 970.75
A7: tier - 3 | B7: 2559.6 | C7: 1872.76 | D7: 777.98
B10: key/observation:
B11: 1.Diabetes patients are higher than normal and prediabetes patients.
B12: 2.In all 3 tiers Diabetes patients are high.
B13: 3.When compared to Normal people prediabetes patients are Low.

Sheet Weight status vs average charge
A3: Row Labels | B3: Average of charges
A4: Normal Weight | B4: 17346.316
A5: Obesity | B5: 10474.625
A6: Over Weight | B6: 13633.365
A7: Under Weight | B7: 24782.334
A8: Grand Total | B8: 13529.918

Sheet Hospital tier vs BMI total
A3: Row Labels | B3: Sum of BMI
A4: tier - 3 | B4: 21584.41
A5: Grand Total | B5: 21584.41

Sheet Weight status vs children Total
A3: Row Labels | B3: Sum of children
A4: Normal Weight | B4: 474
A5: Obesity | B5: 1182
A6: Over Weight | B6: 567
A7: Under Weight | B7: 172
A8: Grand Total | B8: 2395

Sheet Number of surgery vs State ID
A3: Row Labels | B3: Sum of Number of Major Surgeries | C3: Sum of BMI | D3: Sum of charges
A4: R1026 | B4: 43 | C4: 2551.055 | D4: 1049153.4
A5: Grand Total | B5: 43 | C5: 2551.055 | D5: 1049153.4

Sheet SUM OF HBA1C BY HEART ISSUE
A3: Heart Issues | B3: Sum of HBA1C
A4: Yes | B4: 6095.03

Sheet Health Care
A1: Customer ID | B1: Last Name | C1: Title | D1: First Name | E1: Date of Birth | F1: children | G1: charges | H1: Hospital tier | I1: City tier | J1: State ID | K1: Age | L1: BMI | M1: HBA1C | N1: Heart Issues | O1: Any Transplants | P1: Cancer history | Q1: Number of Major Surgeries | R1: Smoker | S1: Weight Status | T1: Diabetes status
A2: Id1 | B2: Hawks | C2: Ms. | D2: Kelly | E2: {=_xlfn.XLOOKUP(A2,'Hospitalisation Details'!A:A,'Hospitalisation Details'!B:H)} -> 25123 | F2: 0 | G2: 63770.43 | H2: tier - 1 | I2: tier - 3 | J2: R1013 | K2: 54 | L2: {=_xlfn.XLOOKUP(A2,'Medical Examinations'!A:A,'Medical Examinations'!B:J)} -> 0 | M2: 0 | N2: Check | O2: 0 | P2: 0 | Q2: 0.67623126 | R2: No | S2: Under Weight | T2: Normal
A3: Id2 | B3: Lehner | C3: Mr. | D3: Matthew D | E3: {=_xlfn.XLOOKUP(A3,'Hospitalisation Details'!A:A,'Hospitalisation Details'!B:H)} -> 28284 | F3: 0 | G3: 62592.87 | H3: tier - 2 | I3: tier - 3 | J3: R1013 | K3: 46 | L3: {=_xlfn.XLOOKUP(A3,'Medical Examinations'!A:A,'Medical Examinations'!B:J)} -> 0 | M3: 0 | N3: Check | O3: 0 | P3: 0 | Q3: 0.67623126 | R3: No | S3: Under Weight | T3: Normal
A4: Id3 | B4: Lu | C4: Mr. | D4: Phil | E4: {=_xlfn.XLOOKUP(A4,'Hospitalisation Details'!A:A,'Hospitalisation Details'!B:H)} -> 25822 | F4: 3 | G4: 60021.4 | H4: tier - 1 | I4: tier - 1 | J4: R1012 | K4: 52 | L4: {=_xlfn.XLOOKUP(A4,'Medical Examinations'!A:A,'Medical Examinations'!B:J)} -> 0 | M4: 0 | N4: Check | O4: 0 | P4: 0 | Q4: 0.67623126 | R4: No | S4: Under Weight | T4: Normal
A5: Id4 | B5: Osborne | C5: Ms. | D5: Kelsey | E5: {=_xlfn.XLOOKUP(A5,'Hospitalisation Details'!A:A,'Hospitalisation Details'!B:H)} -> 33395 | F5: 1 | G5: 58571.07 | H5: tier - 1 | I5: tier - 3 | J5: R1024 | K5: 32 | L5: {=_xlfn.XLOOKUP(A5,'Medical Examinations'!A:A,'Medical Examinations'!B:J)} -> 0 | M5: 0 | N5: Check | O5: 0 | P5: 0 | Q5: 0.67623126 | R5: No | S5: Under Weight | T5: Normal
A6: Id5 | B6: Kadala | C6: Ms. | D6: Kristyn | E6: {=_xlfn.XLOOKUP(A6,'Hospitalisation Details'!A:A,'Hospitalisation Details'!B:H)} -> 32678 | F6: 0 | G6: 55135.4 | H6: tier - 1 | I6: tier - 2 | J6: R1012 | K6: 33 | L6: {=_xlfn.XLOOKUP(A6,'Medical Examinations'!A:A,'Medical Examinations'!B:J)} -> 0 | M6: 0 | N6: Check | O6: 0 | P6: 0 | Q6: 0.67623126 | R6: No | S6: Under Weight | T6: Normal
A7: Id6 | B7: Baker | C7: Mr. | D7: Russell B. | E7: {=_xlfn.XLOOKUP(A7,'Hospitalisation Details'!A:A,'Hospitalisation Details'!B:H)} -> 22862 | F7: 0 | G7: 52590.83 | H7: tier - 1 | I7: tier - 3 | J7: R1011 | K7: 60 | L7: {=_xlfn.XLOOKUP(A7,'Medical Examinations'!A:A,'Medical Examinations'!B:J)} -> 0 | M7: 0 | N7: Check | O7: 0 | P7: 0 | Q7: 0.67623126 | R7: No | S7: Under Weight | T7: Normal
A8: Id7 | B8: Macpherson | C8: Mr. | D8: Scott | E8: {=_xlfn.XLOOKUP(A8,'Hospitalisation Details'!A:A,'Hospitalisation Details'!B:H)} -> 34634 | F8: 1 | G8: 51194.56 | H8: tier - 1 | I8: tier - 3 | J8: R1011 | K8: 28 | L8: {=_xlfn.XLOOKUP(A8,'Medical Examinations'!A:A,'Medical Examinations'!B:J)} -> 0 | M8: 0 | N8: Check | O8: 0 | P8: 0 | Q8: 0.67623126 | R8: No | S8: Under Weight | T8: Normal
A9: Id8 | B9: Hallman | C9: Mr. | D9: Stephen | E9: {=_xlfn.XLOOKUP(A9,'Hospitalisation Details'!A:A,'Hospitalisation Details'!B:H)} -> 21363 | F9: 2 | G9: 49577.66 | H9: tier - 2 | I9: tier - 2 | J9: R1013 | K9: 64 | L9: {=_xlfn.XLOOKUP(A9,'Medical Examinations'!A:A,'Medical Examinations'!B:J)} -> 0 | M9: 0 | N9: Check | O9: 0 | P9: 0 | Q9: 0.67623126 | R9: No | S9: Under Weight | T9: Normal
A10: Id9 | B10: Moran | C10: Mr. | D10: Patrick R. | E10: {=_xlfn.XLOOKUP(A10,'Hospitalisation Details'!A:A,'Hospitalisation Details'!B:H)} -> 23258 | F10: 1 | G10: 48970.25 | H10: tier - 1 | I10: tier - 2 | J10: R1013 | K10: 59 | L10: {=_xlfn.XLOOKUP(A10,'Medical Examinations'!A:A,'Medical Examinations'!B:J)} -> 17.58 | M10: 4.51 | N10: No | O10: No | P10: No | Q10: 1 | R10: No | S10: Under Weight | T10: Normal
A11: Id10 | B11: Benner | C11: Ms. | D11: Brooke N. | E11: {=_xlfn.XLOOKUP(A11,'Hospitalisation Details'!A:A,'Hospitalisation Details'!B:H)} -> 28853 | F11: 0 | G11: 48885.14 | H11: tier - 1 | I11: tier - 2 | J11: R1013 | K11: 44 | L11: {=_xlfn.XLOOKUP(A11,'Medical Examinations'!A:A,'Medical Examinations'!B:J)} -> 17.6 | M11: 4.39 | N11: No | O11: No | P11: No | Q11: 1 | R11: No | S11: Under Weight | T11: Normal
A12: Id11 | B12: Fierro Vargas | C12: Ms. | D12: Paola Andrea | E12: {=_xlfn.XLOOKUP(A12,'Hospitalisation Details'!A:A,'Hospitalisation Details'!B:H)} -> 21753 | F12: 0 | G12: 48824.45 | H12: tier - 2 | I12: tier - 1 | J12: R1011 | K12: 63 | L12: {=_xlfn.XLOOKUP(A12,'Medical Examinations'!A:A,'Medical Examinations'!B:J)} -> 16.47 | M12: 6.35 | N12: No | O12: No | P12: Yes | Q12: 1 | R12: No | S12: Under Weight | T12: Prediabetes
A13: Id12 | B13: Franz | C13: Mr. | D13: David | E13: {=_xlfn.XLOOKUP(A13,'Hospitalisation Details'!A:A,'Hospitalisation Details'!B:H)} -> 24042 | F13: 1 | G13: 48675.52 | H13: tier - 1 | I13: tier - 2 | J13: R1013 | K13: 57 | L13: {=_xlfn.XLOOKUP(A13,'Medical Examinations'!A:A,'Medical Examinations'!B:J)} -> 17.7 | M13: 6.28 | N13: No | O13: No | P13: No | Q13: 1 | R13: No | S13: Under Weight | T13: Prediabetes
A14: Id13 | B14: Foster | C14: Mr. | D14: Wade | E14: {=_xlfn.XLOOKUP(A14,'Hospitalisation Details'!A:A,'Hospitalisation Details'!B:H)} -> 22930 | F14: 0 | G14: 48673.56 | H14: tier - 1 | I14: tier - 2 | J14: R1013 | K14: 60 | L14: {=_xlfn.XLOOKUP(A14,'Medical Examinations'!A:A,'Medical Examinations'!B:J)} -> 22.34 | M14: 5.57 | N14: No | O14: No | P14: No | Q14: 1 | R14: No | S14: Normal Weight | T14: Normal
A15: Id14 | B15: Tenorio | C15: Mr. | D15: Franklin | E15: {=_xlfn.XLOOKUP(A15,'Hospitalisation Details'!A:A,'Hospitalisation Details'!B:H)} -> 25173 | F15: 3 | G15: 48549.18 | H15: tier - 1 | I15: tier - 3 | J15: R1016 | K15: 54 | L15: {=_xlfn.XLOOKUP(A15,'Medical Examinations'!A:A,'Medical Examinations'!B:J)} -> 22.24 | M15: 4.29 | N15: Yes | O15: No | P15: No | Q15: 0 | R15: No | S15: Normal Weight | T15: Normal
A16: Id15 | B16: Rios | C16: Ms. | D16: Leilani M. | E16: {=_xlfn.XLOOKUP(A16,'Hospitalisation Details'!A:A,'Hospitalisation Details'!B:H)} -> 22636 | F16: 1 | G16: 48517.56 | H16: tier - 1 | I16: tier - 3 | J16: R1024 | K16: 61 | L16: {=_xlfn.XLOOKUP(A16,'Medical Examinations'!A:A,'Medical Examinations'!B:J)} -> 17.07 | M16: 5.22 | N16: No | O16: No | P16: Yes | Q16: 1 | R16: No | S16: Under Weight | T16: Normal
A17: Id16 | B17: Viau-Dupuis | C17: Mr. | D17: Philippe | E17: {=_xlfn.XLOOKUP(A17,'Hospitalisation Details'!A:A,'Hospitalisation Details'!B:H)} -> 22885 | F17: 0 | G17: 48173.36 | H17: tier - 1 | I17: tier - 3 | J17: R1011 | K17: 60 | L17: {=_xlfn.XLOOKUP(A17,'Medical Examinations'!A:A,'Medical Examinations'!B:J)} -> 17.82 | M17: 5.26 | N17: Yes | O17: No | P17: No | Q17: 1 | R17: No | S17: Under Weight | T17: Normal
A18: Id17 | B18: Cronin | C18: Ms. | D18: Jennifer A. | E18: {=_xlfn.XLOOKUP(A18,'Hospitalisation Details'!A:A,'Hospitalisation Details'!B:H)} -> 21505 | F18: 1 | G18: 47928.03 | H18: tier - 2 | I18: tier - 3 | J18: R1011 | K18: 64 | L18: {=_xlfn.XLOOKUP(A18,'Medical Examinations'!A:A,'Medical Examinations'!B:J)} -> 21.77 | M18: 10.67 | N18: No | O18: No | P18: No | Q18: 0 | R18: No | S18: Normal Weight | T18: Diabetes
A19: Id18 | B19: Noordstar | C19: Ms. | D19: Christina M. | E19: {=_xlfn.XLOOKUP(A19,'Hospitalisation Details'!A:A,'Hospitalisation Details'!B:H)} -> 23228 | F19: 1 | G19: 47896.79 | H19: tier - 1 | I19: tier - 3 | J19: R1024 | K19: 59 | L19: {=_xlfn.XLOOKUP(A19,'Medical Examinations'!A:A,'Medical Examinations'!B:J)} -> 20.1 | M19: 5.6 | N19: Yes | O19: No | P19: Yes | Q19: 1 | R19: No | S19: Normal Weight | T19: Normal
A20: Id19 | B20: Boudalia | C20: Mr. | D20: Said Sr. | E20: {=_xlfn.XLOOKUP(A20,'Hospitalisation Details'!A:A,'Hospitalisation Details'!B:H)} -> 23688 | F20: 2 | G20: 47496.49 | H20: tier - 1 | I20: tier - 3 | J20: R1012 | K20: 58 | L20: {=_xlfn.XLOOKUP(A20,'Medical Examinations'!A:A,'Medical Examinations'!B:J)} -> 24.76 | M20: 4.54 | N20: Yes | O20: No | P20: No | Q20: 0 | R20: No | S20: Normal Weight | T20: Normal
A21: Id20 | B21: Flor | C21: Mr. | D21: John | E21: {=_xlfn.XLOOKUP(A21,'Hospitalisation Details'!A:A,'Hospitalisation Details'!B:H)} -> 26203 | F21: 2 | G21: 47462.89 | H21: tier - 1 | I21: tier - 2 | J21: R1013 | K21: 51 | L21: {=_xlfn.XLOOKUP(A21,'Medical Examinations'!A:A,'Medical Examinations'!B:J)} -> 22.24 | M21: 5.04 | N21: No | O21: No | P21: No | Q21: 0 | R21: No | S21: Normal Weight | T21: Normal
... A1286: Id1285 | B1286: Bokun | C1286: Ms. | D1286: Rebecca E | E1286: {=_xlfn.XLOOKUP(A1286,'Hospitalisation Details'!A:A,'Hospitalisation Details'!B:H)} -> 27612 | F1286: 1 | G1286: 8551.35 | H1286: tier - 2 | I1286: tier - 2 | J1286: R1011 | K1286: 47 | L1286: {=_xlfn.XLOOKUP(A1286,'Medical Examinations'!A:A,'Medical Examinations'!B:J)} -> 29.39 | M1286: 4.52 | N1286: Yes | O1286: No | P1286: No | Q1286: 0 | R1286: No | S1286: Over Weight | T1286: Normal
A1287: Id1286 | B1287: Ainsley | C1287: Ms. | D1287: Katie M. | E1287: {=_xlfn.XLOOKUP(A1287,'Hospitalisation Details'!A:A,'Hospitalisation Details'!B:H)} -> 12-12-1982.84152071764 | F1287: 1 | G1287: 8547.69 | H1287: tier - 2 | I1287: tier - 1 | J1287: R1013 | K1287: #VALUE! | L1287: {=_xlfn.XLOOKUP(A1287,'Medical Examinations'!A:A,'Medical Examinations'!B:J)} -> 24.29 | M1287: 9.05 | N1287: No | O1287: No | P1287: No | Q1287: 0 | R1287: No | S1287: Normal Weight | T1287: Diabetes
A1288: Id1287 | B1288: Foster | C1288: Ms. | D1288: Elizabeth A. | E1288: {=_xlfn.XLOOKUP(A1288,'Hospitalisation Details'!A:A,'Hospitalisation Details'!B:H)} -> 27704 | F1288: 1 | G1288: 8539.67 | H1288: tier - 2 | I1288: tier - 3 | J1288: R1011 | K1288: 47 | L1288: {=_xlfn.XLOOKUP(A1288,'Medical Examinations'!A:A,'Medical Examinations'!B:J)} -> 30.22 | M1288: 4.65 | N1288: No | O1288: No | P1288: No | Q1288: 0 | R1288: No | S1288: Obesity | T1288: Normal
A1289: Id1288 | B1289: Overpeck | C1289: Ms. | D1289: Sarah | E1289: {=_xlfn.XLOOKUP(A1289,'Hospitalisation Details'!A:A,'Hospitalisation Details'!B:H)} -> 29947 | F1289: 3 | G1289: 8538.29 | H1289: tier - 2 | I1289: tier - 3 | J1289: R1024 | K1289: 41 | L1289: {=_xlfn.XLOOKUP(A1289,'Medical Examinations'!A:A,'Medical Examinations'!B:J)} -> 29.1 | M1289: 5.64 | N1289: Yes | O1289: No | P1289: No | Q1289: 0 | R1289: No | S1289: Over Weight | T1289: Normal
A1290: Id1289 | B1290: Levine | C1290: Ms. | D1290: Annie J. | E1290: {=_xlfn.XLOOKUP(A1290,'Hospitalisation Details'!A:A,'Hospitalisation Details'!B:H)} -> 24-7-1982.84152071764 | F1290: 0 | G1290: 8534.67 | H1290: tier - 2 | I1290: tier - 3 | J1290: R1024 | K1290: #VALUE! | L1290: {=_xlfn.XLOOKUP(A1290,'Medical Examinations'!A:A,'Medical Examinations'!B:J)} -> 28.16 | M1290: 5.56 | N1290: No | O1290: No | P1290: No | Q1290: 2 | R1290: No | S1290: Over Weight | T1290: Normal
A1291: Id1290 | B1291: Jean | C1291: Ms. | D1291: Annie | E1291: {=_xlfn.XLOOKUP(A1291,'Hospitalisation Details'!A:A,'Hospitalisation Details'!B:H)} -> 28332 | F1291: 2 | G1291: 8527.53 | H1291: tier - 2 | I1291: tier - 2 | J1291: R1013 | K1291: 45 | L1291: {=_xlfn.XLOOKUP(A1291,'Medical Examinations'!A:A,'Medical Examinations'!B:J)} -> 30.5 | M1291: 11.94 | N1291: Yes | O1291: No | P1291: No | Q1291: 0 | R1291: No | S1291: Obesity | T1291: Diabetes
A1292: Id1291 | B1292: Wild | C1292: Ms. | D1292: Lindsey | E1292: {=_xlfn.XLOOKUP(A1292,'Hospitalisation Details'!A:A,'Hospitalisation Details'!B:H)} -> 29080 | F1292: 3 | G1292: 8522 | H1292: tier - 2 | I1292: tier - 2 | J1292: R1011 | K1292: 43 | L1292: {=_xlfn.XLOOKUP(A1292,'Medical Examinations'!A:A,'Medical Examinations'!B:J)} -> 37.1 | M1292: 7.19 | N1292: Yes | O1292: No | P1292: No | Q1292: 0 | R1292: No | S1292: Obesity | T1292: Diabetes
A1293: Id1292 | B1293: Tabor | C1293: Ms. | D1293: Laura | E1293: {=_xlfn.XLOOKUP(A1293,'Hospitalisation Details'!A:A,'Hospitalisation Details'!B:H)} -> 28488 | F1293: 2 | G1293: 8520.03 | H1293: tier - 2 | I1293: tier - 3 | J1293: R1011 | K1293: 45 | L1293: {=_xlfn.XLOOKUP(A1293,'Medical Examinations'!A:A,'Medical Examinations'!B:J)} -> 45.51 | M1293: 4.32 | N1293: No | O1293: No | P1293: No | Q1293: 1 | R1293: No | S1293: Obesity | T1293: Normal
A1294: Id1293 | B1294: Steffen | C1294: Ms. | D1294: Amy T | E1294: {=_xlfn.XLOOKUP(A1294,'Hospitalisation Details'!A:A,'Hospitalisation Details'!B:H)} -> 28297 | F1294: 2 | G1294: 8516.83 | H1294: tier - 2 | I1294: tier - 1 | J1294: R1013 | K1294: 45 | L1294: {=_xlfn.XLOOKUP(A1294,'Medical Examinations'!A:A,'Medical Examinations'!B:J)} -> 35.625 | M1294: 10.79 | N1294: No | O1294: No | P1294: No | Q1294: 0 | R1294: No | S1294: Obesity | T1294: Diabetes
A1295: Id1294 | B1295: Tadich | C1295: Ms. | D1295: Katarina D | E1295: {=_xlfn.XLOOKUP(A1295,'Hospitalisation Details'!A:A,'Hospitalisation Details'!B:H)} -> 28485 | F1295: 2 | G1295: 8515.76 | H1295: tier - 2 | I1295: tier - 2 | J1295: R1013 | K1295: 45 | L1295: {=_xlfn.XLOOKUP(A1295,'Medical Examinations'!A:A,'Medical Examinations'!B:J)} -> 35.42 | M1295: 8.7 | N1295: Yes | O1295: No | P1295: No | Q1295: 1 | R1295: No | S1295: Obesity | T1295: Diabetes
A1296: Id1295 | B1296: Christenson | C1296: Mr. | D1296: B.j. | E1296: {=_xlfn.XLOOKUP(A1296,'Hospitalisation Details'!A:A,'Hospitalisation Details'!B:H)} -> 34283 | F1296: 0 | G1296: 8471.65 | H1296: tier - 2 | I1296: tier - 1 | J1296: R1012 | K1296: 29 | L1296: {=_xlfn.XLOOKUP(A1296,'Medical Examinations'!A:A,'Medical Examinations'!B:J)} -> 38.14 | M1296: 5.84 | N1296: No | O1296: No | P1296: No | Q1296: 0 | R1296: No | S1296: Obesity | T1296: Prediabetes
A1297: Id1296 | B1297: Shell | C1297: Ms. | D1297: Alison | E1297: {=_xlfn.XLOOKUP(A1297,'Hospitalisation Details'!A:A,'Hospitalisation Details'!B:H)} -> 33856 | F1297: 0 | G1297: 8466.35 | H1297: tier - 2 | I1297: tier - 2 | J1297: R1012 | K1297: 30 | L1297: {=_xlfn.XLOOKUP(A1297,'Medical Examinations'!A:A,'Medical Examinations'!B:J)} -> 21.5 | M1297: 9.77 | N1297: Yes | O1297: No | P1297: No | Q1297: 0 | R1297: No | S1297: Normal Weight | T1297: Diabetes
A1298: Id1297 | B1298: Rao | C1298: Mr. | D1298: Neil K. | E1298: {=_xlfn.XLOOKUP(A1298,'Hospitalisation Details'!A:A,'Hospitalisation Details'!B:H)} -> 26659 | F1298: 0 | G1298: 8457.82 | H1298: tier - 2 | I1298: tier - 3 | J1298: R1011 | K1298: 50 | L1298: {=_xlfn.XLOOKUP(A1298,'Medical Examinations'!A:A,'Medical Examinations'!B:J)} -> 33.4 | M1298: 4.84 | N1298: No | O1298: No | P1298: No | Q1298: 0 | R1298: No | S1298: Obesity | T1298: Normal
A1299: Id1298 | B1299: Myers | C1299: Mrs. | D1299: Anne Hunter | E1299: {=_xlfn.XLOOKUP(A1299,'Hospitalisation Details'!A:A,'Hospitalisation Details'!B:H)} -> 30852 | F1299: 3 | G1299: 8450.82 | H1299: tier - 2 | I1299: tier - 2 | J1299: R1025 | K1299: 38 | L1299: {=_xlfn.XLOOKUP(A1299,'Medical Examinations'!A:A,'Medical Examinations'!B:J)} -> 28.975 | M1299: 7.69 | N1299: Yes | O1299: No | P1299: No | Q1299: 0 | R1299: No | S1299: Over Weight | T1299: Diabetes
A1300: Id1299 | B1300: McLean | C1300: Ms. | D1300: Sandra | E1300: {=_xlfn.XLOOKUP(A1300,'Hospitalisation Details'!A:A,'Hospitalisation Details'!B:H)} -> 24270 | F1300: 0 | G1300: 8448.66 | H1300: tier - 3 | I1300: tier - 1 | J1300: R1013 | K1300: 56 | L1300: {=_xlfn.XLOOKUP(A1300,'Medical Examinations'!A:A,'Medical Examinations'!B:J)} -> 30.78 | M1300: 10.74 | N1300: Yes | O1300: No | P1300: No | Q1300: 2 | R1300: No | S1300: Obesity | T1300: Diabetes
A1301: Id1300 | B1301: Gomez | C1301: Mr. | D1301: Robert | E1301: {=_xlfn.XLOOKUP(A1301,'Hospitalisation Details'!A:A,'Hospitalisation Details'!B:H)} -> 26546 | F1301: 0 | G1301: 8444.47 | H1301: tier - 3 | I1301: tier - 1 | J1301: R1011 | K1301: 50 | L1301: {=_xlfn.XLOOKUP(A1301,'Medical Examinations'!A:A,'Medical Examinations'!B:J)} -> 33.3 | M1301: 8.26 | N1301: Yes | O1301: No | P1301: No | Q1301: 2 | R1301: No | S1301: Obesity | T1301: Diabetes
A1302: Id1301 | B1302: Hemingway | C1302: Mr. | D1302: Rodney | E1302: {=_xlfn.XLOOKUP(A1302,'Hospitalisation Details'!A:A,'Hospitalisation Details'!B:H)} -> 26551 | F1302: 0 | G1302: 8442.67 | H1302: tier - 2 | I1302: tier - 3 | J1302: R1013 | K1302: 50 | L1302: {=_xlfn.XLOOKUP(A1302,'Medical Examinations'!A:A,'Medical Examinations'!B:J)} -> 32.67 | M1302: 11.81 | N1302: Yes | O1302: No | P1302: No | Q1302: 0 | R1302: No | S1302: Obesity | T1302: Diabetes
... A2336: Id2335 | B2336: German | C2336: Mr. | D2336: Aaron K | E2336: {=_xlfn.XLOOKUP(A2336,'Hospitalisation Details'!A:A,'Hospitalisation Details'!B:H)} -> 33794 | F2336: 0 | G2336: 563.84 | H2336: tier - 2 | I2336: tier - 3 | J2336: R1013 | K2336: 30 | L2336: {=_xlfn.XLOOKUP(A2336,'Medical Examinations'!A:A,'Medical Examinations'!B:J)} -> 47.41 | M2336: 7.47 | N2336: No | O2336: No | P2336: No | Q2336: 0 | R2336: yes | S2336: Obesity | T2336: Diabetes

Sheet Dashboard
A1: HEALTH CARE DASHBOARD
